<?xml version="1.0" ?>
<robot name="(Unsaved)" xmlns:xacro="http://www.ros.org/wiki/xacro">

<xacro:include filename="$(find (Unsaved)_description)/urdf/materials.xacro" />
<xacro:include filename="$(find (Unsaved)_description)/urdf/(Unsaved).trans" />
<xacro:include filename="$(find (Unsaved)_description)/urdf/(Unsaved).gazebo" />
<link name="base_link">
  <inertial>
    <origin xyz="0.1099699446546728 -0.002774626814158729 -0.04250000000000002" rpy="0 0 0"/>
    <mass value="0.520537202641438"/>
    <inertia ixx="0.000296" iyy="0.001339" izz="0.001152" ixy="7.5e-05" iyz="-0.0" ixz="-0.0"/>
  </inertial>
  <visual>
    <origin xyz="0 0 0" rpy="0 0 0"/>
    <geometry>
      <mesh filename="package://(Unsaved)_description/meshes/base_link.stl" scale="0.001 0.001 0.001"/>
    </geometry>
    <material name="silver"/>
  </visual>
  <collision>
    <origin xyz="0 0 0" rpy="0 0 0"/>
    <geometry>
      <mesh filename="package://(Unsaved)_description/meshes/base_link.stl" scale="0.001 0.001 0.001"/>
    </geometry>
  </collision>
</link>

<link name="leftwheel_1">
  <inertial>
    <origin xyz="-1.3736157952748407e-07 0.0 0.0025" rpy="0 0 0"/>
    <mass value="0.06242442777453344"/>
    <inertia ixx="8e-06" iyy="8e-06" izz="1.6e-05" ixy="0.0" iyz="0.0" ixz="0.0"/>
  </inertial>
  <visual>
    <origin xyz="-0.155366 0.015 0.005" rpy="0 0 0"/>
    <geometry>
      <mesh filename="package://(Unsaved)_description/meshes/leftwheel_1.stl" scale="0.001 0.001 0.001"/>
    </geometry>
    <material name="silver"/>
  </visual>
  <collision>
    <origin xyz="-0.155366 0.015 0.005" rpy="0 0 0"/>
    <geometry>
      <mesh filename="package://(Unsaved)_description/meshes/leftwheel_1.stl" scale="0.001 0.001 0.001"/>
    </geometry>
  </collision>
</link>

<link name="rightwheel_1">
  <inertial>
    <origin xyz="2.3096799750543795e-09 -2.235174233200521e-10 -0.0025000000000000022" rpy="0 0 0"/>
    <mass value="0.06242442777453344"/>
    <inertia ixx="8e-06" iyy="8e-06" izz="1.6e-05" ixy="0.0" iyz="0.0" ixz="0.0"/>
  </inertial>
  <visual>
    <origin xyz="-0.155 0.015 0.08" rpy="0 0 0"/>
    <geometry>
      <mesh filename="package://(Unsaved)_description/meshes/rightwheel_1.stl" scale="0.001 0.001 0.001"/>
    </geometry>
    <material name="silver"/>
  </visual>
  <collision>
    <origin xyz="-0.155 0.015 0.08" rpy="0 0 0"/>
    <geometry>
      <mesh filename="package://(Unsaved)_description/meshes/rightwheel_1.stl" scale="0.001 0.001 0.001"/>
    </geometry>
  </collision>
</link>

<link name="mount_1">
  <inertial>
    <origin xyz="0.019999999999999997 0.0024999999999999996 0.0" rpy="0 0 0"/>
    <mass value="0.035324999999999995"/>
    <inertia ixx="3e-06" iyy="5e-06" izz="3e-06" ixy="0.0" iyz="0.0" ixz="-0.0"/>
  </inertial>
  <visual>
    <origin xyz="-0.025 -0.005 0.0425" rpy="0 0 0"/>
    <geometry>
      <mesh filename="package://(Unsaved)_description/meshes/mount_1.stl" scale="0.001 0.001 0.001"/>
    </geometry>
    <material name="silver"/>
  </visual>
  <collision>
    <origin xyz="-0.025 -0.005 0.0425" rpy="0 0 0"/>
    <geometry>
      <mesh filename="package://(Unsaved)_description/meshes/mount_1.stl" scale="0.001 0.001 0.001"/>
    </geometry>
  </collision>
</link>

<link name="lidar_1">
  <inertial>
    <origin xyz="-3.469446951953614e-17 0.004499999999999999 -6.938893903907228e-18" rpy="0 0 0"/>
    <mass value="0.03468023765251854"/>
    <inertia ixx="2e-06" iyy="3e-06" izz="2e-06" ixy="0.0" iyz="-0.0" ixz="0.0"/>
  </inertial>
  <visual>
    <origin xyz="-0.045 -0.01 0.0425" rpy="0 0 0"/>
    <geometry>
      <mesh filename="package://(Unsaved)_description/meshes/lidar_1.stl" scale="0.001 0.001 0.001"/>
    </geometry>
    <material name="silver"/>
  </visual>
  <collision>
    <origin xyz="-0.045 -0.01 0.0425" rpy="0 0 0"/>
    <geometry>
      <mesh filename="package://(Unsaved)_description/meshes/lidar_1.stl" scale="0.001 0.001 0.001"/>
    </geometry>
  </collision>
</link>

<joint name="Rev1" type="continuous">
  <origin xyz="0.155366 -0.015 -0.005" rpy="0 0 0"/>
  <parent link="base_link"/>
  <child link="leftwheel_1"/>
  <axis xyz="0.0 0.0 1.0"/>
</joint>

<joint name="Rev2" type="continuous">
  <origin xyz="0.155 -0.015 -0.08" rpy="0 0 0"/>
  <parent link="base_link"/>
  <child link="rightwheel_1"/>
  <axis xyz="0.0 0.0 -1.0"/>
</joint>

<joint name="Rigid3" type="fixed">
  <origin xyz="0.025 0.005 -0.0425" rpy="0 0 0"/>
  <parent link="base_link"/>
  <child link="mount_1"/>
</joint>

<joint name="Rev4" type="continuous">
  <origin xyz="0.02 0.005 0.0" rpy="0 0 0"/>
  <parent link="mount_1"/>
  <child link="lidar_1"/>
  <axis xyz="0.0 1.0 0.0"/>
</joint>

</robot>
